Starting harness run
Run ID: conda-env-conflict-resolution-revised_trial1_20250930164934
Harness execution failed for tasks/conda-env-conflict-resolution-revised: Command '['docker', 'compose', '-p', 'conda-env-conflict-resolution-revised-1-of-1-conda-env-conflict-resolution-revised_trial1_20250930164934', '-f', '/Users/arijit/Desktop/projects/benchmarking/benchmarks/tasks/terminal-bench/tasks/conda-env-conflict-resolution-revised/docker-compose.yaml', 'build']' returned non-zero exit status 1.
Traceback (most recent call last):
  File "/Users/arijit/Desktop/projects/benchmarking/benchmarks/tasks/terminal-bench/terminal_bench/harness/harness.py", line 1011, in _execute_single_trial
    trial_results = self._run_trial(trial_handler)
                    ^^^^^^^^^^^^^^^^^^^^^^^^^^^^^^
  File "/Users/arijit/Desktop/projects/benchmarking/benchmarks/tasks/terminal-bench/terminal_bench/harness/harness.py", line 717, in _run_trial
    with spin_up_terminal(
         ^^^^^^^^^^^^^^^^^
  File "/usr/local/Cellar/python@3.12/3.12.11_1/Frameworks/Python.framework/Versions/3.12/lib/python3.12/contextlib.py", line 137, in __enter__
    return next(self.gen)
           ^^^^^^^^^^^^^^
  File "/Users/arijit/Desktop/projects/benchmarking/benchmarks/tasks/terminal-bench/terminal_bench/terminal/terminal.py", line 176, in spin_up_terminal
    terminal.start()
  File "/Users/arijit/Desktop/projects/benchmarking/benchmarks/tasks/terminal-bench/terminal_bench/terminal/terminal.py", line 102, in start
    self.container = self._compose_manager.start()
                     ^^^^^^^^^^^^^^^^^^^^^^^^^^^^^
  File "/Users/arijit/Desktop/projects/benchmarking/benchmarks/tasks/terminal-bench/terminal_bench/terminal/docker_compose_manager.py", line 126, in start
    self._run_docker_compose_command(["build"])
  File "/Users/arijit/Desktop/projects/benchmarking/benchmarks/tasks/terminal-bench/terminal_bench/terminal/docker_compose_manager.py", line 101, in _run_docker_compose_command
    result = subprocess.run(
             ^^^^^^^^^^^^^^^
  File "/usr/local/Cellar/python@3.12/3.12.11_1/Frameworks/Python.framework/Versions/3.12/lib/python3.12/subprocess.py", line 571, in run
    raise CalledProcessError(retcode, process.args,
subprocess.CalledProcessError: Command '['docker', 'compose', '-p', 'conda-env-conflict-resolution-revised-1-of-1-conda-env-conflict-resolution-revised_trial1_20250930164934', '-f', '/Users/arijit/Desktop/projects/benchmarking/benchmarks/tasks/terminal-bench/tasks/conda-env-conflict-resolution-revised/docker-compose.yaml', 'build']' returned non-zero exit status 1.
Running tasks (1/1, Accuracy: 0.00%) - Last: conda-env-conflict… … 

Results Summary:
+-------------------+---------+
| Metric            | Value   |
+===================+=========+
| Resolved Trials   | 0       |
+-------------------+---------+
| Unresolved Trials | 1       |
+-------------------+---------+
| Accuracy          | 0.00%   |
+-------------------+---------+

Results written to 
/Users/arijit/Desktop/projects/benchmarking/benchmarks/tasks/termin
al-bench/M4_raw_logs/runs_conda-env-conflict-resolution-revised_202
50930164934/conda-env-conflict-resolution-revised_trial1_2025093016
4934/results.json
